<?xml version="1.0" encoding="utf-8"?>
<!-- This URDF was automatically created by SolidWorks to URDF Exporter! Originally created by Stephen Brawner (brawner@gmail.com) 
     Commit Version: 1.6.0-4-g7f85cfe  Build Version: 1.6.7995.38578
     For more information, please see http://wiki.ros.org/sw_urdf_exporter -->
<robot
  name="arm">
  <link name="world"/>
  <link
    name="base_link">
    <inertial>
      <origin
        xyz="-1.96622295617639E-18 0.00491577000004411 -0.0300068310515828"
        rpy="0 0 0" />
      <mass
        value="0.144089467104784" />
      <inertia
        ixx="0.000572165456461746"
        ixy="-1.87969362331846E-21"
        ixz="8.89514678276613E-21"
        iyy="0.000738669236937651"
        iyz="9.95023472728905E-22"
        izz="0.000167999664039735" />
    </inertial>
    <visual>
      <origin
        xyz="0 0 0"
        rpy="0 0 0" />
      <geometry>
        <mesh
          filename="package://curie_robot_description/arm/meshes/base_link.STL" />
      </geometry>
      <material
        name="">
        <color
          rgba="0.792156862745098 0.819607843137255 0.933333333333333 1" />
      </material>
    </visual>
    <collision>
      <origin
        xyz="0 0 0"
        rpy="0 0 0" />
      <geometry>
        <mesh
          filename="package://curie_robot_description/arm/meshes/base_link.STL" />
      </geometry>
    </collision>
  </link>
  <joint name="world_to_base" type="fixed">
    <parent link="world"/>
    <child link="base_link"/>
    <origin xyz="0 0 0" rpy="0 0 0"/>
  </joint>
  <link
    name="shoulder_Link">
    <inertial>
      <origin
        xyz="-0.000715904680960492 0.0830840430310779 0.00812192398664151"
        rpy="0 0 0" />
      <mass
        value="0.20025804803982" />
      <inertia
        ixx="0.00045528826225594"
        ixy="8.42535610844755E-07"
        ixz="-6.61580139352349E-06"
        iyy="0.000141303075248095"
        iyz="-9.5615374950996E-06"
        izz="0.000529769493184708" />
    </inertial>
    <visual>
      <origin
        xyz="0 0 0"
        rpy="0 0 0" />
      <geometry>
        <mesh
          filename="package://curie_robot_description/arm/meshes/shoulder_Link.STL" />
      </geometry>
      <material
        name="">
        <color
          rgba="0.792156862745098 0.819607843137255 0.933333333333333 1" />
      </material>
    </visual>
    <collision>
      <origin
        xyz="0 0 0"
        rpy="0 0 0" />
      <geometry>
        <mesh
          filename="package://curie_robot_description/arm/meshes/shoulder_Link.STL" />
      </geometry>
    </collision>
  </link>
  <joint
    name="base_rotation"
    type="continuous">
    <origin
      xyz="0 0 0"
      rpy="1.5708 0 0.087908" />
    <parent
      link="base_link" />
    <child
      link="shoulder_Link" />
    <axis
      xyz="0 1 0" />
  </joint>
  <link
    name="bicep_Link">
    <inertial>
      <origin
        xyz="0.0100139209792384 0.043016103837474 0.0800268035724994"
        rpy="0 0 0" />
      <mass
        value="0.71055376786355" />
      <inertia
        ixx="0.00175286865449129"
        ixy="-0.000517704877587934"
        ixz="-3.22464238359028E-05"
        iyy="0.000600488986038592"
        iyz="-4.21684450007355E-05"
        izz="0.00213116565305193" />
    </inertial>
    <visual>
      <origin
        xyz="0 0 0"
        rpy="0 0 0" />
      <geometry>
        <mesh
          filename="package://curie_robot_description/arm/meshes/bicep_Link.STL" />
      </geometry>
      <material
        name="">
        <color
          rgba="0.792156862745098 0.819607843137255 0.933333333333333 1" />
      </material>
    </visual>
    <collision>
      <origin
        xyz="0 0 0"
        rpy="0 0 0" />
      <geometry>
        <mesh
          filename="package://curie_robot_description/arm/meshes/bicep_Link.STL" />
      </geometry>
    </collision>
  </link>
  <joint
    name="shoulder_joint"
    type="continuous">
    <origin
      xyz="0 0.22114 0"
      rpy="-0.031089 0.0056647 0.36044" />
    <parent
      link="shoulder_Link" />
    <child
      link="bicep_Link" />
    <axis
      xyz="0.087795 0 -0.99614" />
  </joint>
  <link
    name="forearm_Link">
    <inertial>
      <origin
        xyz="0.043460017584096 -0.332622708191764 0.0362624165998042"
        rpy="0 0 0" />
      <mass
        value="0.443962186668402" />
      <inertia
        ixx="0.00176869849333801"
        ixy="4.68572881809625E-05"
        ixz="-8.82949088154214E-07"
        iyy="0.000169824536382791"
        iyz="9.75584691985591E-07"
        izz="0.0017766410934104" />
    </inertial>
    <visual>
      <origin
        xyz="0 0 0"
        rpy="0 0 0" />
      <geometry>
        <mesh
          filename="package://curie_robot_description/arm/meshes/forearm_Link.STL" />
      </geometry>
      <material
        name="">
        <color
          rgba="0.792156862745098 0.819607843137255 0.933333333333333 1" />
      </material>
    </visual>
    <collision>
      <origin
        xyz="0 0 0"
        rpy="0 0 0" />
      <geometry>
        <mesh
          filename="package://curie_robot_description/arm/meshes/forearm_Link.STL" />
      </geometry>
    </collision>
  </link>
  <joint
    name="elbow_joint"
    type="continuous">
    <origin
      xyz="0.20793 0.43928 0.018326"
      rpy="-0.081535 0.027551 1.1836" />
    <parent
      link="bicep_Link" />
    <child
      link="forearm_Link" />
    <axis
      xyz="0.060581 0 -0.99816" />
  </joint>
  <link
    name="wrist_link">
    <inertial>
      <origin
        xyz="0.0512136021299031 0.00247818437159464 -0.00165107325292069"
        rpy="0 0 0" />
      <mass
        value="0.170674141371088" />
      <inertia
        ixx="5.30788635434232E-05"
        ixy="5.02321763796355E-07"
        ixz="-2.05384134426534E-06"
        iyy="5.17964591221056E-05"
        iyz="6.05398088066751E-06"
        izz="5.45304104757224E-05" />
    </inertial>
    <visual>
      <origin
        xyz="0 0 0"
        rpy="0 0 0" />
      <geometry>
        <mesh
          filename="package://curie_robot_description/arm/meshes/wrist_link.STL" />
      </geometry>
      <material
        name="">
        <color
          rgba="0.792156862745098 0.819607843137255 0.933333333333333 1" />
      </material>
    </visual>
    <collision>
      <origin
        xyz="0 0 0"
        rpy="0 0 0" />
      <geometry>
        <mesh
          filename="package://curie_robot_description/arm/meshes/wrist_link.STL" />
      </geometry>
    </collision>
  </link>
  <joint
    name="wrist_pitch"
    type="continuous">
    <origin
      xyz="0.049101 -0.49007 0.022058"
      rpy="-2.3345 -1.5102 -3.1416" />
    <parent
      link="forearm_Link" />
    <child
      link="wrist_link" />
    <axis
      xyz="1 0 0" />
  </joint>
  <link
    name="endeffector_link">
    <inertial>
      <origin
        xyz="1.12044955973695E-06 0.00873566776571755 -0.0834691422790301"
        rpy="0 0 0" />
      <mass
        value="0.288715575983165" />
      <inertia
        ixx="0.000207381763417261"
        ixy="2.54113099148778E-07"
        ixz="-3.1664107732646E-09"
        iyy="0.000294346134901293"
        iyz="2.31247035795215E-05"
        izz="0.000157204938569964" />
    </inertial>
    <visual>
      <origin
        xyz="0 0 0"
        rpy="0 0 0" />
      <geometry>
        <mesh
          filename="package://curie_robot_description/arm/meshes/endeffector_link.STL" />
      </geometry>
      <material
        name="">
        <color
          rgba="0.792156862745098 0.819607843137255 0.933333333333333 1" />
      </material>
    </visual>
    <collision>
      <origin
        xyz="0 0 0"
        rpy="0 0 0" />
      <geometry>
        <mesh
          filename="package://curie_robot_description/arm/meshes/endeffector_link.STL" />
      </geometry>
    </collision>
  </link>
  <joint
    name="wrist_roll"
    type="continuous">
    <origin
      xyz="0.03651 -0.0078577 0.0078577"
      rpy="-2.3562 0 0" />
    <parent
      link="wrist_link" />
    <child
      link="endeffector_link" />
    <axis
      xyz="0 0 1" />
  </joint>
  <link
    name="jaw_link">
    <inertial>
      <origin
        xyz="-1.65825271500331E-08 0.007588926067015 0.0436042368928344"
        rpy="0 0 0" />
      <mass
        value="0.0984789337215444" />
      <inertia
        ixx="9.00395484394421E-05"
        ixy="-1.4124066384442E-11"
        ixz="5.24309545284244E-11"
        iyy="0.000115678791223341"
        iyz="3.65078852465512E-07"
        izz="3.86783789559917E-05" />
    </inertial>
    <visual>
      <origin
        xyz="0 0 0"
        rpy="0 0 0" />
      <geometry>
        <mesh
          filename="package://curie_robot_description/arm/meshes/jaw_link.STL" />
      </geometry>
      <material
        name="">
        <color
          rgba="0.792156862745098 0.819607843137255 0.933333333333333 1" />
      </material>
    </visual>
    <collision>
      <origin
        xyz="0 0 0"
        rpy="0 0 0" />
      <geometry>
        <mesh
          filename="package://curie_robot_description/arm/meshes/jaw_link.STL" />
      </geometry>
    </collision>
  </link>
  <joint
    name="gripper"
    type="continuous">
    <origin
      xyz="0 -0.0155 -0.085565"
      rpy="1.5708 0 0" />
    <parent
      link="endeffector_link" />
    <child
      link="jaw_link" />
    <axis
      xyz="1 0 0" />
  </joint>
</robot>